Workbook

Sheet January 2026
E1: Dawn InfoTek Inc.
J2: Contractor:
J3: 1. To be remitted to Manager/Project Leader by the last workday of each month
A4: Resource Name: | F4: Client Manager Name:
A5: Email Address: | F5: Office Phone: | J5: Manager/Project Leader:
A6: Date Submitted: | F6: Department Name: | J6: Please send to timesheet@dawninfotek.com after your approval monthly.
A7: Date Beginning: | F7: Project Leader Name:
A8: Date Ending:
A10: Date | B10: Week | C10: Time Start | D10: Time End | E10: Activity | F10: Regular Hours | G10: Approved O/T | H10: Hours Billed
A11: 46023 | B11: =WEEKNUM(A11, 2) -> 1 | E11: Holiday: New Year’s Day | H11: =SUM(F11:G11) -> 0
A12: =A11+1 -> 46024 | B12: =WEEKNUM(A12, 2) -> 1 | H12: =SUM(F12:G12) -> 0
A13: =A12+1 -> 46025 | B13: =WEEKNUM(A13, 2) -> 1 | H13: =SUM(F13:G13) -> 0
A14: =A13+1 -> 46026 | B14: =WEEKNUM(A14, 2) -> 1 | H14: =SUM(F14:G14) -> 0
A15: Total of Week 1 | F15: =SUMIF($B:$E,RIGHT($A15,2),F:F) -> 0 | G15: =SUMIF($B:$E,RIGHT($A15,2),G:G) -> 0 | H15: =SUMIF($B:$E,RIGHT($A15,2),H:H) -> 0
A17: Date | B17: Week | C17: Time Start | D17: Time End | E17: Activity | F17: Regular Hours | G17: Approved O/T | H17: Hours Billed
A18: =A14+1 -> 46027 | B18: =WEEKNUM(A18, 2) -> 2 | H18: =SUM(F18:G18) -> 0
A19: =A18+1 -> 46028 | B19: =WEEKNUM(A19, 2) -> 2 | H19: =SUM(F19:G19) -> 0
A20: =A19+1 -> 46029 | B20: =WEEKNUM(A20, 2) -> 2 | H20: =SUM(F20:G20) -> 0
A21: =A20+1 -> 46030 | B21: =WEEKNUM(A21, 2) -> 2 | H21: =SUM(F21:G21) -> 0
A22: =A21+1 -> 46031 | B22: =WEEKNUM(A22, 2) -> 2 | H22: =SUM(F22:G22) -> 0
A23: =A22+1 -> 46032 | B23: =WEEKNUM(A23, 2) -> 2 | H23: =SUM(F23:G23) -> 0
A24: =A23+1 -> 46033 | B24: =WEEKNUM(A24, 2) -> 2 | H24: =SUM(F24:G24) -> 0
A25: ="Total of Week "&RIGHT(A15,2)+1 -> Total of Week 2 | F25: =SUMIF($B:$E,RIGHT($A25,2),F:F) -> 0 | G25: =SUMIF($B:$E,RIGHT($A25,2),G:G) -> 0 | H25: =SUMIF($B:$E,RIGHT($A25,2),H:H) -> 0
A27: Date | B27: Week | C27: Time Start | D27: Time End | E27: Activity | F27: Regular Hours | G27: Approved O/T | H27: Hours Billed
A28: =A24+1 -> 46034 | B28: =WEEKNUM(A28, 2) -> 3 | H28: =SUM(F28:G28) -> 0
A29: =A28+1 -> 46035 | B29: =WEEKNUM(A29, 2) -> 3 | H29: =SUM(F29:G29) -> 0
A30: =A29+1 -> 46036 | B30: =WEEKNUM(A30, 2) -> 3 | H30: =SUM(F30:G30) -> 0
A31: =A30+1 -> 46037 | B31: =WEEKNUM(A31, 2) -> 3 | H31: =SUM(F31:G31) -> 0
A32: =A31+1 -> 46038 | B32: =WEEKNUM(A32, 2) -> 3 | H32: =SUM(F32:G32) -> 0
A33: =A32+1 -> 46039 | B33: =WEEKNUM(A33, 2) -> 3 | H33: =SUM(F33:G33) -> 0
A34: =A33+1 -> 46040 | B34: =WEEKNUM(A34, 2) -> 3 | H34: =SUM(F34:G34) -> 0
A35: ="Total of Week "&RIGHT(A25,2)+1 -> Total of Week 3 | F35: =SUMIF($B:$E,RIGHT($A35,2),F:F) -> 0 | G35: =SUMIF($B:$E,RIGHT($A35,2),G:G) -> 0 | H35: =SUMIF($B:$E,RIGHT($A35,2),H:H) -> 0
A37: Date | B37: Week | C37: Time Start | D37: Time End | E37: Activity | F37: Regular Hours | G37: Approved O/T | H37: Hours Billed
A38: =A34+1 -> 46041 | B38: =WEEKNUM(A38, 2) -> 4 | H38: =SUM(F38:G38) -> 0
A39: =A38+1 -> 46042 | B39: =WEEKNUM(A39, 2) -> 4 | H39: =SUM(F39:G39) -> 0
A40: =A39+1 -> 46043 | B40: =WEEKNUM(A40, 2) -> 4 | H40: =SUM(F40:G40) -> 0
A41: =A40+1 -> 46044 | B41: =WEEKNUM(A41, 2) -> 4 | H41: =SUM(F41:G41) -> 0
A42: =A41+1 -> 46045 | B42: =WEEKNUM(A42, 2) -> 4 | H42: =SUM(F42:G42) -> 0
A43: =A42+1 -> 46046 | B43: =WEEKNUM(A43, 2) -> 4 | H43: =SUM(F43:G43) -> 0
A44: =A43+1 -> 46047 | B44: =WEEKNUM(A44, 2) -> 4 | H44: =SUM(F44:G44) -> 0
...

Sheet February 2026
E1: Dawn InfoTek Inc.
J2: Contractor:
J3: 1. To be remitted to Manager/Project Leader by the last workday of each month
A4: Resource Name: | F4: Client Manager Name:
A5: Email Address: | F5: Office Phone: | J5: Manager/Project Leader:
A6: Date Submitted: | F6: Department Name: | J6: Please send to timesheet@dawninfotek.com after your approval monthly.
A7: Date Beginning: | F7: Project Leader Name:
A8: Date Ending:
A10: Date | B10: Week | C10: Time Start | D10: Time End | E10: Activity | F10: Regular Hours | G10: Approved O/T | H10: Hours Billed
A11: ='January 2026'!A53+1 -> 46054 | B11: =WEEKNUM(A11, 2) -> 5 | H11: =SUM(F11:G11) -> 0
A12: Total of Week 5 | F12: =SUMIF($B:$E,RIGHT($A12,2),F:F) -> 0 | G12: =SUMIF($B:$E,RIGHT($A12,2),G:G) -> 0 | H12: =SUMIF($B:$E,RIGHT($A12,2),H:H) -> 0
A14: Date | B14: Week | C14: Time Start | D14: Time End | E14: Activity | F14: Regular Hours | G14: Approved O/T | H14: Hours Billed
A15: =A11+1 -> 46055 | B15: =WEEKNUM(A15, 2) -> 6 | H15: =SUM(F15:G15) -> 0
A16: =A15+1 -> 46056 | B16: =WEEKNUM(A16, 2) -> 6 | H16: =SUM(F16:G16) -> 0
A17: =A16+1 -> 46057 | B17: =WEEKNUM(A17, 2) -> 6 | H17: =SUM(F17:G17) -> 0
A18: =A17+1 -> 46058 | B18: =WEEKNUM(A18, 2) -> 6 | H18: =SUM(F18:G18) -> 0
A19: =A18+1 -> 46059 | B19: =WEEKNUM(A19, 2) -> 6 | H19: =SUM(F19:G19) -> 0
A20: =A19+1 -> 46060 | B20: =WEEKNUM(A20, 2) -> 6 | H20: =SUM(F20:G20) -> 0
A21: =A20+1 -> 46061 | B21: =WEEKNUM(A21, 2) -> 6 | H21: =SUM(F21:G21) -> 0
A22: ="Total of Week "&RIGHT(A12,2)+1 -> Total of Week 6 | F22: =SUMIF($B:$E,RIGHT($A22,2),F:F) -> 0 | G22: =SUMIF($B:$E,RIGHT($A22,2),G:G) -> 0 | H22: =SUMIF($B:$E,RIGHT($A22,2),H:H) -> 0
A24: Date | B24: Week | C24: Time Start | D24: Time End | E24: Activity | F24: Regular Hours | G24: Approved O/T | H24: Hours Billed
A25: =A21+1 -> 46062 | B25: =WEEKNUM(A25, 2) -> 7 | H25: =SUM(F25:G25) -> 0
A26: =A25+1 -> 46063 | B26: =WEEKNUM(A26, 2) -> 7 | H26: =SUM(F26:G26) -> 0
A27: =A26+1 -> 46064 | B27: =WEEKNUM(A27, 2) -> 7 | H27: =SUM(F27:G27) -> 0
A28: =A27+1 -> 46065 | B28: =WEEKNUM(A28, 2) -> 7 | H28: =SUM(F28:G28) -> 0
A29: =A28+1 -> 46066 | B29: =WEEKNUM(A29, 2) -> 7 | H29: =SUM(F29:G29) -> 0
A30: =A29+1 -> 46067 | B30: =WEEKNUM(A30, 2) -> 7 | H30: =SUM(F30:G30) -> 0
A31: =A30+1 -> 46068 | B31: =WEEKNUM(A31, 2) -> 7 | H31: =SUM(F31:G31) -> 0
A32: ="Total of Week "&RIGHT(A22,2)+1 -> Total of Week 7 | F32: =SUMIF($B:$E,RIGHT($A32,2),F:F) -> 0 | G32: =SUMIF($B:$E,RIGHT($A32,2),G:G) -> 0 | H32: =SUMIF($B:$E,RIGHT($A32,2),H:H) -> 0
A34: Date | B34: Week | C34: Time Start | D34: Time End | E34: Activity | F34: Regular Hours | G34: Approved O/T | H34: Hours Billed
A35: =A31+1 -> 46069 | B35: =WEEKNUM(A35, 2) -> 8 | E35: Holiday: Family Day | H35: =SUM(F35:G35) -> 0
A36: =A35+1 -> 46070 | B36: =WEEKNUM(A36, 2) -> 8 | H36: =SUM(F36:G36) -> 0
A37: =A36+1 -> 46071 | B37: =WEEKNUM(A37, 2) -> 8 | H37: =SUM(F37:G37) -> 0
A38: =A37+1 -> 46072 | B38: =WEEKNUM(A38, 2) -> 8 | H38: =SUM(F38:G38) -> 0
A39: =A38+1 -> 46073 | B39: =WEEKNUM(A39, 2) -> 8 | H39: =SUM(F39:G39) -> 0
A40: =A39+1 -> 46074 | B40: =WEEKNUM(A40, 2) -> 8 | H40: =SUM(F40:G40) -> 0
A41: =A40+1 -> 46075 | B41: =WEEKNUM(A41, 2) -> 8 | H41: =SUM(F41:G41) -> 0
A42: ="Total of Week "&RIGHT(A32,2)+1 -> Total of Week 8 | F42: =SUMIF($B:$E,RIGHT($A42,2),F:F) -> 0 | G42: =SUMIF($B:$E,RIGHT($A42,2),G:G) -> 0 | H42: =SUMIF($B:$E,RIGHT($A42,2),H:H) -> 0
A44: Date | B44: Week | C44: Time Start | D44: Time End | E44: Activity | F44: Regular Hours | G44: Approved O/T | H44: Hours Billed
A45: =A41+1 -> 46076 | B45: =WEEKNUM(A45, 2) -> 9 | H45: =SUM(F45:G45) -> 0
...

Sheet March 2026
E1: Dawn InfoTek Inc.
J2: Contractor:
J3: 1. To be remitted to Manager/Project Leader by the last workday of each month
A4: Resource Name: | F4: Client Manager Name:
A5: Email Address: | F5: Office Phone: | J5: Manager/Project Leader:
A6: Date Submitted: | F6: Department Name: | J6: Please send to timesheet@dawninfotek.com after your approval monthly.
A7: Date Beginning: | F7: Project Leader Name:
A8: Date Ending:
A10: Date | B10: Week | C10: Time Start | D10: Time End | E10: Activity | F10: Regular Hours | G10: Approved O/T | H10: Hours Billed
A11: ='February 2026'!A50+1 -> 46082 | B11: =WEEKNUM(A11, 2) -> 9 | H11: =SUM(F11:G11) -> 0
A12: Total of Week 9 | F12: =SUMIF($B:$E,RIGHT($A12,1),F:F) -> 0 | G12: =SUMIF($B:$E,RIGHT($A12,1),G:G) -> 0 | H12: =SUMIF($B:$E,RIGHT($A12,1),H:H) -> 0
A14: Date | B14: Week | C14: Time Start | D14: Time End | E14: Activity | F14: Regular Hours | G14: Approved O/T | H14: Hours Billed
A15: =A11+1 -> 46083 | B15: =WEEKNUM(A15, 2) -> 10 | H15: =SUM(F15:G15) -> 0
A16: =A15+1 -> 46084 | B16: =WEEKNUM(A16, 2) -> 10 | H16: =SUM(F16:G16) -> 0
A17: =A16+1 -> 46085 | B17: =WEEKNUM(A17, 2) -> 10 | H17: =SUM(F17:G17) -> 0
A18: =A17+1 -> 46086 | B18: =WEEKNUM(A18, 2) -> 10 | H18: =SUM(F18:G18) -> 0
A19: =A18+1 -> 46087 | B19: =WEEKNUM(A19, 2) -> 10 | H19: =SUM(F19:G19) -> 0
A20: =A19+1 -> 46088 | B20: =WEEKNUM(A20, 2) -> 10 | H20: =SUM(F20:G20) -> 0
A21: =A20+1 -> 46089 | B21: =WEEKNUM(A21, 2) -> 10 | H21: =SUM(F21:G21) -> 0
A22: ="Total of Week "&RIGHT(A12,2)+1 -> Total of Week 10 | F22: =SUMIF($B:$E,RIGHT($A22,2),F:F) -> 0 | G22: =SUMIF($B:$E,RIGHT($A22,2),G:G) -> 0 | H22: =SUMIF($B:$E,RIGHT($A22,2),H:H) -> 0
A24: Date | B24: Week | C24: Time Start | D24: Time End | E24: Activity | F24: Regular Hours | G24: Approved O/T | H24: Hours Billed
A25: =A21+1 -> 46090 | B25: =WEEKNUM(A25, 2) -> 11 | H25: =SUM(F25:G25) -> 0
A26: =A25+1 -> 46091 | B26: =WEEKNUM(A26, 2) -> 11 | H26: =SUM(F26:G26) -> 0
A27: =A26+1 -> 46092 | B27: =WEEKNUM(A27, 2) -> 11 | H27: =SUM(F27:G27) -> 0
A28: =A27+1 -> 46093 | B28: =WEEKNUM(A28, 2) -> 11 | H28: =SUM(F28:G28) -> 0
A29: =A28+1 -> 46094 | B29: =WEEKNUM(A29, 2) -> 11 | H29: =SUM(F29:G29) -> 0
A30: =A29+1 -> 46095 | B30: =WEEKNUM(A30, 2) -> 11 | H30: =SUM(F30:G30) -> 0
A31: =A30+1 -> 46096 | B31: =WEEKNUM(A31, 2) -> 11 | H31: =SUM(F31:G31) -> 0
A32: ="Total of Week "&RIGHT(A22,2)+1 -> Total of Week 11 | F32: =SUMIF($B:$E,RIGHT($A32,2),F:F) -> 0 | G32: =SUMIF($B:$E,RIGHT($A32,2),G:G) -> 0 | H32: =SUMIF($B:$E,RIGHT($A32,2),H:H) -> 0
A34: Date | B34: Week | C34: Time Start | D34: Time End | E34: Activity | F34: Regular Hours | G34: Approved O/T | H34: Hours Billed
A35: =A31+1 -> 46097 | B35: =WEEKNUM(A35, 2) -> 12 | H35: =SUM(F35:G35) -> 0
A36: =A35+1 -> 46098 | B36: =WEEKNUM(A36, 2) -> 12 | H36: =SUM(F36:G36) -> 0
A37: =A36+1 -> 46099 | B37: =WEEKNUM(A37, 2) -> 12 | H37: =SUM(F37:G37) -> 0
A38: =A37+1 -> 46100 | B38: =WEEKNUM(A38, 2) -> 12 | H38: =SUM(F38:G38) -> 0
A39: =A38+1 -> 46101 | B39: =WEEKNUM(A39, 2) -> 12 | H39: =SUM(F39:G39) -> 0
A40: =A39+1 -> 46102 | B40: =WEEKNUM(A40, 2) -> 12 | H40: =SUM(F40:G40) -> 0
A41: =A40+1 -> 46103 | B41: =WEEKNUM(A41, 2) -> 12 | H41: =SUM(F41:G41) -> 0
A42: ="Total of Week "&RIGHT(A32,2)+1 -> Total of Week 12 | F42: =SUMIF($B:$E,RIGHT($A42,2),F:F) -> 0 | G42: =SUMIF($B:$E,RIGHT($A42,2),G:G) -> 0 | H42: =SUMIF($B:$E,RIGHT($A42,2),H:H) -> 0
A44: Date | B44: Week | C44: Time Start | D44: Time End | E44: Activity | F44: Regular Hours | G44: Approved O/T | H44: Hours Billed
A45: =A41+1 -> 46104 | B45: =WEEKNUM(A45, 2) -> 13 | H45: =SUM(F45:G45) -> 0
...

Sheet April 2026
E1: Dawn InfoTek Inc.
J2: Contractor:
J3: 1. To be remitted to Manager/Project Leader by the last workday of each month
A4: Resource Name: | F4: Client Manager Name:
A5: Email Address: | F5: Office Phone: | J5: Manager/Project Leader:
A6: Date Submitted: | F6: Department Name: | J6: Please send to timesheet@dawninfotek.com after your approval monthly.
A7: Date Beginning: | F7: Project Leader Name:
A8: Date Ending:
A10: Date | B10: Week | C10: Time Start | D10: Time End | E10: Activity | F10: Regular Hours | G10: Approved O/T | H10: Hours Billed
A11: ='March 2026'!A56+1 -> 46113 | B11: =WEEKNUM(A11, 2) -> 14 | H11: =SUM(F11:G11) -> 0
A12: =A11+1 -> 46114 | B12: =WEEKNUM(A12, 2) -> 14 | H12: =SUM(F12:G12) -> 0
A13: =A12+1 -> 46115 | B13: =WEEKNUM(A13, 2) -> 14 | E13: Holiday: Good Friday | H13: =SUM(F13:G13) -> 0
A14: =A13+1 -> 46116 | B14: =WEEKNUM(A14, 2) -> 14 | H14: =SUM(F14:G14) -> 0
A15: =A14+1 -> 46117 | B15: =WEEKNUM(A15, 2) -> 14 | H15: =SUM(F15:G15) -> 0
A16: Total of Week 14 | F16: =SUMIF($B:$E,RIGHT($A16,2),F:F) -> 0 | G16: =SUMIF($B:$E,RIGHT($A16,2),G:G) -> 0 | H16: =SUMIF($B:$E,RIGHT($A16,2),H:H) -> 0
A18: Date | B18: Week | C18: Time Start | D18: Time End | E18: Activity | F18: Regular Hours | G18: Approved O/T | H18: Hours Billed
A19: =A15+1 -> 46118 | B19: =WEEKNUM(A19, 2) -> 15 | H19: =SUM(F19:G19) -> 0
A20: =A19+1 -> 46119 | B20: =WEEKNUM(A20, 2) -> 15 | H20: =SUM(F20:G20) -> 0
A21: =A20+1 -> 46120 | B21: =WEEKNUM(A21, 2) -> 15 | H21: =SUM(F21:G21) -> 0
A22: =A21+1 -> 46121 | B22: =WEEKNUM(A22, 2) -> 15 | H22: =SUM(F22:G22) -> 0
A23: =A22+1 -> 46122 | B23: =WEEKNUM(A23, 2) -> 15 | H23: =SUM(F23:G23) -> 0
A24: =A23+1 -> 46123 | B24: =WEEKNUM(A24, 2) -> 15 | H24: =SUM(F24:G24) -> 0
A25: =A24+1 -> 46124 | B25: =WEEKNUM(A25, 2) -> 15 | H25: =SUM(F25:G25) -> 0
A26: ="Total of Week "&RIGHT(A16,2)+1 -> Total of Week 15 | F26: =SUMIF($B:$E,RIGHT($A26,2),F:F) -> 0 | G26: =SUMIF($B:$E,RIGHT($A26,2),G:G) -> 0 | H26: =SUMIF($B:$E,RIGHT($A26,2),H:H) -> 0
A28: Date | B28: Week | C28: Time Start | D28: Time End | E28: Activity | F28: Regular Hours | G28: Approved O/T | H28: Hours Billed
A29: =A25+1 -> 46125 | B29: =WEEKNUM(A29, 2) -> 16 | H29: =SUM(F29:G29) -> 0
A30: =A29+1 -> 46126 | B30: =WEEKNUM(A30, 2) -> 16 | H30: =SUM(F30:G30) -> 0
A31: =A30+1 -> 46127 | B31: =WEEKNUM(A31, 2) -> 16 | H31: =SUM(F31:G31) -> 0
A32: =A31+1 -> 46128 | B32: =WEEKNUM(A32, 2) -> 16 | H32: =SUM(F32:G32) -> 0
A33: =A32+1 -> 46129 | B33: =WEEKNUM(A33, 2) -> 16 | H33: =SUM(F33:G33) -> 0
A34: =A33+1 -> 46130 | B34: =WEEKNUM(A34, 2) -> 16 | H34: =SUM(F34:G34) -> 0
A35: =A34+1 -> 46131 | B35: =WEEKNUM(A35, 2) -> 16 | H35: =SUM(F35:G35) -> 0
A36: ="Total of Week "&RIGHT(A26,2)+1 -> Total of Week 16 | F36: =SUMIF($B:$E,RIGHT($A36,2),F:F) -> 0 | G36: =SUMIF($B:$E,RIGHT($A36,2),G:G) -> 0 | H36: =SUMIF($B:$E,RIGHT($A36,2),H:H) -> 0
A38: Date | B38: Week | C38: Time Start | D38: Time End | E38: Activity | F38: Regular Hours | G38: Approved O/T | H38: Hours Billed
A39: =A35+1 -> 46132 | B39: =WEEKNUM(A39, 2) -> 17 | H39: =SUM(F39:G39) -> 0
A40: =A39+1 -> 46133 | B40: =WEEKNUM(A40, 2) -> 17 | H40: =SUM(F40:G40) -> 0
A41: =A40+1 -> 46134 | B41: =WEEKNUM(A41, 2) -> 17 | H41: =SUM(F41:G41) -> 0
A42: =A41+1 -> 46135 | B42: =WEEKNUM(A42, 2) -> 17 | H42: =SUM(F42:G42) -> 0
A43: =A42+1 -> 46136 | B43: =WEEKNUM(A43, 2) -> 17 | H43: =SUM(F43:G43) -> 0
A44: =A43+1 -> 46137 | B44: =WEEKNUM(A44, 2) -> 17 | H44: =SUM(F44:G44) -> 0
...

Sheet May 2026
E1: Dawn InfoTek Inc.
J2: Contractor:
J3: 1. To be remitted to Manager/Project Leader by the last workday of each month
A4: Resource Name: | F4: Client Manager Name:
A5: Email Address: | F5: Office Phone: | J5: Manager/Project Leader:
A6: Date Submitted: | F6: Department Name: | J6: Please send to timesheet@dawninfotek.com after your approval monthly.
A7: Date Beginning: | F7: Project Leader Name:
A8: Date Ending:
A10: Date | B10: Week | C10: Time Start | D10: Time End | E10: Activity | F10: Regular Hours | G10: Approved O/T | H10: Hours Billed
A11: ='April 2026'!A52+1 -> 46143 | B11: =WEEKNUM(A11, 2) -> 18 | H11: =SUM(F11:G11) -> 0
A12: =A11+1 -> 46144 | B12: =WEEKNUM(A12, 2) -> 18 | H12: =SUM(F12:G12) -> 0
A13: =A12+1 -> 46145 | B13: =WEEKNUM(A13, 2) -> 18 | H13: =SUM(F13:G13) -> 0
A14: Total of Week 18 | F14: =SUMIF($B:$E,RIGHT($A14,2),F:F) -> 0 | G14: =SUMIF($B:$E,RIGHT($A14,2),G:G) -> 0 | H14: =SUMIF($B:$E,RIGHT($A14,2),H:H) -> 0
A16: Date | B16: Week | C16: Time Start | D16: Time End | E16: Activity | F16: Regular Hours | G16: Approved O/T | H16: Hours Billed
A17: =A13+1 -> 46146 | B17: =WEEKNUM(A17, 2) -> 19 | H17: =SUM(F17:G17) -> 0
A18: =A17+1 -> 46147 | B18: =WEEKNUM(A18, 2) -> 19 | H18: =SUM(F18:G18) -> 0
A19: =A18+1 -> 46148 | B19: =WEEKNUM(A19, 2) -> 19 | H19: =SUM(F19:G19) -> 0
A20: =A19+1 -> 46149 | B20: =WEEKNUM(A20, 2) -> 19 | H20: =SUM(F20:G20) -> 0
A21: =A20+1 -> 46150 | B21: =WEEKNUM(A21, 2) -> 19 | H21: =SUM(F21:G21) -> 0
A22: =A21+1 -> 46151 | B22: =WEEKNUM(A22, 2) -> 19 | H22: =SUM(F22:G22) -> 0
A23: =A22+1 -> 46152 | B23: =WEEKNUM(A23, 2) -> 19 | H23: =SUM(F23:G23) -> 0
A24: ="Total of Week "&RIGHT(A14,2)+1 -> Total of Week 19 | F24: =SUMIF($B:$E,RIGHT($A24,2),F:F) -> 0 | G24: =SUMIF($B:$E,RIGHT($A24,2),G:G) -> 0 | H24: =SUMIF($B:$E,RIGHT($A24,2),H:H) -> 0
A26: Date | B26: Week | C26: Time Start | D26: Time End | E26: Activity | F26: Regular Hours | G26: Approved O/T | H26: Hours Billed
A27: =A23+1 -> 46153 | B27: =WEEKNUM(A27, 2) -> 20 | H27: =SUM(F27:G27) -> 0
A28: =A27+1 -> 46154 | B28: =WEEKNUM(A28, 2) -> 20 | H28: =SUM(F28:G28) -> 0
A29: =A28+1 -> 46155 | B29: =WEEKNUM(A29, 2) -> 20 | H29: =SUM(F29:G29) -> 0
A30: =A29+1 -> 46156 | B30: =WEEKNUM(A30, 2) -> 20 | H30: =SUM(F30:G30) -> 0
A31: =A30+1 -> 46157 | B31: =WEEKNUM(A31, 2) -> 20 | H31: =SUM(F31:G31) -> 0
A32: =A31+1 -> 46158 | B32: =WEEKNUM(A32, 2) -> 20 | H32: =SUM(F32:G32) -> 0
A33: =A32+1 -> 46159 | B33: =WEEKNUM(A33, 2) -> 20 | H33: =SUM(F33:G33) -> 0
A34: ="Total of Week "&RIGHT(A24,2)+1 -> Total of Week 20 | F34: =SUMIF($B:$E,RIGHT($A34,2),F:F) -> 0 | G34: =SUMIF($B:$E,RIGHT($A34,2),G:G) -> 0 | H34: =SUMIF($B:$E,RIGHT($A34,2),H:H) -> 0
A36: Date | B36: Week | C36: Time Start | D36: Time End | E36: Activity | F36: Regular Hours | G36: Approved O/T | H36: Hours Billed
A37: =A33+1 -> 46160 | B37: =WEEKNUM(A37, 2) -> 21 | E37: Holiday: Victoria Day | H37: =SUM(F37:G37) -> 0
A38: =A37+1 -> 46161 | B38: =WEEKNUM(A38, 2) -> 21 | H38: =SUM(F38:G38) -> 0
A39: =A38+1 -> 46162 | B39: =WEEKNUM(A39, 2) -> 21 | H39: =SUM(F39:G39) -> 0
A40: =A39+1 -> 46163 | B40: =WEEKNUM(A40, 2) -> 21 | H40: =SUM(F40:G40) -> 0
A41: =A40+1 -> 46164 | B41: =WEEKNUM(A41, 2) -> 21 | H41: =SUM(F41:G41) -> 0
A42: =A41+1 -> 46165 | B42: =WEEKNUM(A42, 2) -> 21 | H42: =SUM(F42:G42) -> 0
A43: =A42+1 -> 46166 | B43: =WEEKNUM(A43, 2) -> 21 | H43: =SUM(F43:G43) -> 0
A44: ="Total of Week "&RIGHT(A34,2)+1 -> Total of Week 21 | F44: =SUMIF($B:$E,RIGHT($A44,2),F:F) -> 0 | G44: =SUMIF($B:$E,RIGHT($A44,2),G:G) -> 0 | H44: =SUMIF($B:$E,RIGHT($A44,2),H:H) -> 0
...

Sheet June 2026
E1: Dawn InfoTek Inc.
J2: Contractor:
J3: 1. To be remitted to Manager/Project Leader by the last workday of each month
A4: Resource Name: | F4: Client Manager Name:
A5: Email Address: | F5: Office Phone: | J5: Manager/Project Leader:
A6: Date Submitted: | F6: Department Name: | J6: Please send to timesheet@dawninfotek.com after your approval monthly.
A7: Date Beginning: | F7: Project Leader Name:
A8: Date Ending:
A10: Date | B10: Week | C10: Time Start | D10: Time End | E10: Activity | F10: Regular Hours | G10: Approved O/T | H10: Hours Billed
A11: ='May 2026'!A53+1 -> 46174 | B11: =WEEKNUM(A11, 2) -> 23 | H11: =SUM(F11:G11) -> 0
A12: =A11+1 -> 46175 | B12: =WEEKNUM(A12, 2) -> 23 | H12: =SUM(F12:G12) -> 0
A13: =A12+1 -> 46176 | B13: =WEEKNUM(A13, 2) -> 23 | H13: =SUM(F13:G13) -> 0
A14: =A13+1 -> 46177 | B14: =WEEKNUM(A14, 2) -> 23 | H14: =SUM(F14:G14) -> 0
A15: =A14+1 -> 46178 | B15: =WEEKNUM(A15, 2) -> 23 | H15: =SUM(F15:G15) -> 0
A16: =A15+1 -> 46179 | B16: =WEEKNUM(A16, 2) -> 23 | H16: =SUM(F16:G16) -> 0
A17: =A16+1 -> 46180 | B17: =WEEKNUM(A17, 2) -> 23 | H17: =SUM(F17:G17) -> 0
A18: ="Total of Week "&RIGHT(B17,2) -> Total of Week 23 | F18: =SUMIF($B:$E,RIGHT($A18,2),F:F) -> 0 | G18: =SUMIF($B:$E,RIGHT($A18,2),G:G) -> 0 | H18: =SUMIF($B:$E,RIGHT($A18,2),H:H) -> 0
A20: Date | B20: Week | C20: Time Start | D20: Time End | E20: Activity | F20: Regular Hours | G20: Approved O/T | H20: Hours Billed
A21: =A17+1 -> 46181 | B21: =WEEKNUM(A21, 2) -> 24 | H21: =SUM(F21:G21) -> 0
A22: =A21+1 -> 46182 | B22: =WEEKNUM(A22, 2) -> 24 | H22: =SUM(F22:G22) -> 0
A23: =A22+1 -> 46183 | B23: =WEEKNUM(A23, 2) -> 24 | H23: =SUM(F23:G23) -> 0
A24: =A23+1 -> 46184 | B24: =WEEKNUM(A24, 2) -> 24 | H24: =SUM(F24:G24) -> 0
A25: =A24+1 -> 46185 | B25: =WEEKNUM(A25, 2) -> 24 | H25: =SUM(F25:G25) -> 0
A26: =A25+1 -> 46186 | B26: =WEEKNUM(A26, 2) -> 24 | H26: =SUM(F26:G26) -> 0
A27: =A26+1 -> 46187 | B27: =WEEKNUM(A27, 2) -> 24 | H27: =SUM(F27:G27) -> 0
A28: ="Total of Week "&RIGHT(A18,2)+1 -> Total of Week 24 | F28: =SUMIF($B:$E,RIGHT($A28,2),F:F) -> 0 | G28: =SUMIF($B:$E,RIGHT($A28,2),G:G) -> 0 | H28: =SUMIF($B:$E,RIGHT($A28,2),H:H) -> 0
A30: Date | B30: Week | C30: Time Start | D30: Time End | E30: Activity | F30: Regular Hours | G30: Approved O/T | H30: Hours Billed
A31: =A27+1 -> 46188 | B31: =WEEKNUM(A31, 2) -> 25 | H31: =SUM(F31:G31) -> 0
A32: =A31+1 -> 46189 | B32: =WEEKNUM(A32, 2) -> 25 | H32: =SUM(F32:G32) -> 0
A33: =A32+1 -> 46190 | B33: =WEEKNUM(A33, 2) -> 25 | H33: =SUM(F33:G33) -> 0
A34: =A33+1 -> 46191 | B34: =WEEKNUM(A34, 2) -> 25 | H34: =SUM(F34:G34) -> 0
A35: =A34+1 -> 46192 | B35: =WEEKNUM(A35, 2) -> 25 | H35: =SUM(F35:G35) -> 0
A36: =A35+1 -> 46193 | B36: =WEEKNUM(A36, 2) -> 25 | H36: =SUM(F36:G36) -> 0
A37: =A36+1 -> 46194 | B37: =WEEKNUM(A37, 2) -> 25 | H37: =SUM(F37:G37) -> 0
A38: ="Total of Week "&RIGHT(A28,2)+1 -> Total of Week 25 | F38: =SUMIF($B:$E,RIGHT($A38,2),F:F) -> 0 | G38: =SUMIF($B:$E,RIGHT($A38,2),G:G) -> 0 | H38: =SUMIF($B:$E,RIGHT($A38,2),H:H) -> 0
A40: Date | B40: Week | C40: Time Start | D40: Time End | E40: Activity | F40: Regular Hours | G40: Approved O/T | H40: Hours Billed
A41: =A37+1 -> 46195 | B41: =WEEKNUM(A41, 2) -> 26 | H41: =SUM(F41:G41) -> 0
A42: =A41+1 -> 46196 | B42: =WEEKNUM(A42, 2) -> 26 | H42: =SUM(F42:G42) -> 0
A43: =A42+1 -> 46197 | B43: =WEEKNUM(A43, 2) -> 26 | H43: =SUM(F43:G43) -> 0
A44: =A43+1 -> 46198 | B44: =WEEKNUM(A44, 2) -> 26 | H44: =SUM(F44:G44) -> 0
...

Sheet July 2026
E1: Dawn InfoTek Inc.
J2: Contractor:
J3: 1. To be remitted to Manager/Project Leader by the last workday of each month
A4: Resource Name: | F4: Client Manager Name:
A5: Email Address: | F5: Office Phone: | J5: Manager/Project Leader:
A6: Date Submitted: | F6: Department Name: | J6: Please send to timesheet@dawninfotek.com after your approval monthly.
A7: Date Beginning: | F7: Project Leader Name:
A8: Date Ending:
A10: Date | B10: Week | C10: Time Start | D10: Time End | E10: Activity | F10: Regular Hours | G10: Approved O/T | H10: Hours Billed
A11: ='June 2026'!A52+1 -> 46204 | B11: =WEEKNUM(A11, 2) -> 27 | E11: Holiday: Canada Day | H11: =SUM(F11:G11) -> 0
A12: =A11+1 -> 46205 | B12: =WEEKNUM(A12, 2) -> 27 | H12: =SUM(F12:G12) -> 0
A13: =A12+1 -> 46206 | B13: =WEEKNUM(A13, 2) -> 27 | H13: =SUM(F13:G13) -> 0
A14: =A13+1 -> 46207 | B14: =WEEKNUM(A14, 2) -> 27 | H14: =SUM(F14:G14) -> 0
A15: =A14+1 -> 46208 | B15: =WEEKNUM(A15, 2) -> 27 | H15: =SUM(F15:G15) -> 0
A16: Total of Week 27 | F16: =SUMIF($B:$E,RIGHT($A16,2),F:F) -> 0 | G16: =SUMIF($B:$E,RIGHT($A16,2),G:G) -> 0 | H16: =SUMIF($B:$E,RIGHT($A16,2),H:H) -> 0
A18: Date | B18: Week | C18: Time Start | D18: Time End | E18: Activity | F18: Regular Hours | G18: Approved O/T | H18: Hours Billed
A19: =A15+1 -> 46209 | B19: =WEEKNUM(A19, 2) -> 28 | H19: =SUM(F19:G19) -> 0
A20: =A19+1 -> 46210 | B20: =WEEKNUM(A20, 2) -> 28 | H20: =SUM(F20:G20) -> 0
A21: =A20+1 -> 46211 | B21: =WEEKNUM(A21, 2) -> 28 | H21: =SUM(F21:G21) -> 0
A22: =A21+1 -> 46212 | B22: =WEEKNUM(A22, 2) -> 28 | H22: =SUM(F22:G22) -> 0
A23: =A22+1 -> 46213 | B23: =WEEKNUM(A23, 2) -> 28 | H23: =SUM(F23:G23) -> 0
A24: =A23+1 -> 46214 | B24: =WEEKNUM(A24, 2) -> 28 | H24: =SUM(F24:G24) -> 0
A25: =A24+1 -> 46215 | B25: =WEEKNUM(A25, 2) -> 28 | H25: =SUM(F25:G25) -> 0
A26: ="Total of Week "&RIGHT(A16,2)+1 -> Total of Week 28 | F26: =SUMIF($B:$E,RIGHT($A26,2),F:F) -> 0 | G26: =SUMIF($B:$E,RIGHT($A26,2),G:G) -> 0 | H26: =SUMIF($B:$E,RIGHT($A26,2),H:H) -> 0
A28: Date | B28: Week | C28: Time Start | D28: Time End | E28: Activity | F28: Regular Hours | G28: Approved O/T | H28: Hours Billed
A29: =A25+1 -> 46216 | B29: =WEEKNUM(A29, 2) -> 29 | H29: =SUM(F29:G29) -> 0
A30: =A29+1 -> 46217 | B30: =WEEKNUM(A30, 2) -> 29 | H30: =SUM(F30:G30) -> 0
A31: =A30+1 -> 46218 | B31: =WEEKNUM(A31, 2) -> 29 | H31: =SUM(F31:G31) -> 0
A32: =A31+1 -> 46219 | B32: =WEEKNUM(A32, 2) -> 29 | H32: =SUM(F32:G32) -> 0
A33: =A32+1 -> 46220 | B33: =WEEKNUM(A33, 2) -> 29 | H33: =SUM(F33:G33) -> 0
A34: =A33+1 -> 46221 | B34: =WEEKNUM(A34, 2) -> 29 | H34: =SUM(F34:G34) -> 0
A35: =A34+1 -> 46222 | B35: =WEEKNUM(A35, 2) -> 29 | H35: =SUM(F35:G35) -> 0
A36: ="Total of Week "&RIGHT(A26,2)+1 -> Total of Week 29 | F36: =SUMIF($B:$E,RIGHT($A36,2),F:F) -> 0 | G36: =SUMIF($B:$E,RIGHT($A36,2),G:G) -> 0 | H36: =SUMIF($B:$E,RIGHT($A36,2),H:H) -> 0
A38: Date | B38: Week | C38: Time Start | D38: Time End | E38: Activity | F38: Regular Hours | G38: Approved O/T | H38: Hours Billed
A39: =A35+1 -> 46223 | B39: =WEEKNUM(A39, 2) -> 30 | H39: =SUM(F39:G39) -> 0
A40: =A39+1 -> 46224 | B40: =WEEKNUM(A40, 2) -> 30 | H40: =SUM(F40:G40) -> 0
A41: =A40+1 -> 46225 | B41: =WEEKNUM(A41, 2) -> 30 | H41: =SUM(F41:G41) -> 0
A42: =A41+1 -> 46226 | B42: =WEEKNUM(A42, 2) -> 30 | H42: =SUM(F42:G42) -> 0
A43: =A42+1 -> 46227 | B43: =WEEKNUM(A43, 2) -> 30 | H43: =SUM(F43:G43) -> 0
A44: =A43+1 -> 46228 | B44: =WEEKNUM(A44, 2) -> 30 | H44: =SUM(F44:G44) -> 0
...

Sheet August 2026
E1: Dawn InfoTek Inc.
J2: Contractor:
J3: 1. To be remitted to Manager/Project Leader by the last workday of each month
A4: Resource Name: | F4: Client Manager Name:
A5: Email Address: | F5: Office Phone: | J5: Manager/Project Leader:
A6: Date Submitted: | F6: Department Name: | J6: Please send to timesheet@dawninfotek.com after your approval monthly.
A7: Date Beginning: | F7: Project Leader Name:
A8: Date Ending:
A10: Date | B10: Week | C10: Time Start | D10: Time End | E10: Activity | F10: Regular Hours | G10: Approved O/T | H10: Hours Billed
A11: ='July 2026'!A53+1 -> 46235 | B11: =WEEKNUM(A11, 2) -> 31 | H11: =SUM(F11:G11) -> 0
A12: =A11+1 -> 46236 | B12: =WEEKNUM(A12, 2) -> 31 | H12: =SUM(F12:G12) -> 0
A13: Total of Week 31 | F13: =SUMIF($B:$E,RIGHT($A13,2),F:F) -> 0 | G13: =SUMIF($B:$E,RIGHT($A13,2),G:G) -> 0 | H13: =SUMIF($B:$E,RIGHT($A13,2),H:H) -> 0
A15: Date | B15: Week | C15: Time Start | D15: Time End | E15: Activity | F15: Regular Hours | G15: Approved O/T | H15: Hours Billed
A16: =A12+1 -> 46237 | B16: =WEEKNUM(A16, 2) -> 32 | E16: Holiday: Civic Holiday | H16: =SUM(F16:G16) -> 0
A17: =A16+1 -> 46238 | B17: =WEEKNUM(A17, 2) -> 32 | H17: =SUM(F17:G17) -> 0
A18: =A17+1 -> 46239 | B18: =WEEKNUM(A18, 2) -> 32 | H18: =SUM(F18:G18) -> 0
A19: =A18+1 -> 46240 | B19: =WEEKNUM(A19, 2) -> 32 | H19: =SUM(F19:G19) -> 0
A20: =A19+1 -> 46241 | B20: =WEEKNUM(A20, 2) -> 32 | H20: =SUM(F20:G20) -> 0
A21: =A20+1 -> 46242 | B21: =WEEKNUM(A21, 2) -> 32 | H21: =SUM(F21:G21) -> 0
A22: =A21+1 -> 46243 | B22: =WEEKNUM(A22, 2) -> 32 | H22: =SUM(F22:G22) -> 0
A23: ="Total of Week "&RIGHT(A13,2)+1 -> Total of Week 32 | F23: =SUMIF($B:$E,RIGHT($A23,2),F:F) -> 0 | G23: =SUMIF($B:$E,RIGHT($A23,2),G:G) -> 0 | H23: =SUMIF($B:$E,RIGHT($A23,2),H:H) -> 0
A25: Date | B25: Week | C25: Time Start | D25: Time End | E25: Activity | F25: Regular Hours | G25: Approved O/T | H25: Hours Billed
A26: =A22+1 -> 46244 | B26: =WEEKNUM(A26, 2) -> 33 | H26: =SUM(F26:G26) -> 0
A27: =A26+1 -> 46245 | B27: =WEEKNUM(A27, 2) -> 33 | H27: =SUM(F27:G27) -> 0
A28: =A27+1 -> 46246 | B28: =WEEKNUM(A28, 2) -> 33 | H28: =SUM(F28:G28) -> 0
A29: =A28+1 -> 46247 | B29: =WEEKNUM(A29, 2) -> 33 | H29: =SUM(F29:G29) -> 0
A30: =A29+1 -> 46248 | B30: =WEEKNUM(A30, 2) -> 33 | H30: =SUM(F30:G30) -> 0
A31: =A30+1 -> 46249 | B31: =WEEKNUM(A31, 2) -> 33 | H31: =SUM(F31:G31) -> 0
A32: =A31+1 -> 46250 | B32: =WEEKNUM(A32, 2) -> 33 | H32: =SUM(F32:G32) -> 0
A33: ="Total of Week "&RIGHT(A23,2)+1 -> Total of Week 33 | F33: =SUMIF($B:$E,RIGHT($A33,2),F:F) -> 0 | G33: =SUMIF($B:$E,RIGHT($A33,2),G:G) -> 0 | H33: =SUMIF($B:$E,RIGHT($A33,2),H:H) -> 0
A35: Date | B35: Week | C35: Time Start | D35: Time End | E35: Activity | F35: Regular Hours | G35: Approved O/T | H35: Hours Billed
A36: =A32+1 -> 46251 | B36: =WEEKNUM(A36, 2) -> 34 | H36: =SUM(F36:G36) -> 0
A37: =A36+1 -> 46252 | B37: =WEEKNUM(A37, 2) -> 34 | H37: =SUM(F37:G37) -> 0
A38: =A37+1 -> 46253 | B38: =WEEKNUM(A38, 2) -> 34 | H38: =SUM(F38:G38) -> 0
A39: =A38+1 -> 46254 | B39: =WEEKNUM(A39, 2) -> 34 | H39: =SUM(F39:G39) -> 0
A40: =A39+1 -> 46255 | B40: =WEEKNUM(A40, 2) -> 34 | H40: =SUM(F40:G40) -> 0
A41: =A40+1 -> 46256 | B41: =WEEKNUM(A41, 2) -> 34 | H41: =SUM(F41:G41) -> 0
A42: =A41+1 -> 46257 | B42: =WEEKNUM(A42, 2) -> 34 | H42: =SUM(F42:G42) -> 0
A43: ="Total of Week "&RIGHT(A33,2)+1 -> Total of Week 34 | F43: =SUMIF($B:$E,RIGHT($A43,2),F:F) -> 0 | G43: =SUMIF($B:$E,RIGHT($A43,2),G:G) -> 0 | H43: =SUMIF($B:$E,RIGHT($A43,2),H:H) -> 0
A45: Date | B45: Week | C45: Time Start | D45: Time End | E45: Activity | F45: Regular Hours | G45: Approved O/T | H45: Hours Billed
...

Sheet September 2026
E1: Dawn InfoTek Inc.
J2: Contractor:
J3: 1. To be remitted to Manager/Project Leader by the last workday of each month
A4: Resource Name: | F4: Client Manager Name:
A5: Email Address: | F5: Office Phone: | J5: Manager/Project Leader:
A6: Date Submitted: | F6: Department Name: | J6: Please send to timesheet@dawninfotek.com after your approval monthly.
A7: Date Beginning: | F7: Project Leader Name:
A8: Date Ending:
A10: Date | B10: Week | C10: Time Start | D10: Time End | E10: Activity | F10: Regular Hours | G10: Approved O/T | H10: Hours Billed
A11: ='August 2026'!A56+1 -> 46266 | B11: =WEEKNUM(A11, 2) -> 36 | H11: =SUM(F11:G11) -> 0
A12: =A11+1 -> 46267 | B12: =WEEKNUM(A12, 2) -> 36 | H12: =SUM(F12:G12) -> 0
A13: =A12+1 -> 46268 | B13: =WEEKNUM(A13, 2) -> 36 | H13: =SUM(F13:G13) -> 0
A14: =A13+1 -> 46269 | B14: =WEEKNUM(A14, 2) -> 36 | H14: =SUM(F14:G14) -> 0
A15: =A14+1 -> 46270 | B15: =WEEKNUM(A15, 2) -> 36 | H15: =SUM(F15:G15) -> 0
A16: =A15+1 -> 46271 | B16: =WEEKNUM(A16, 2) -> 36 | H16: =SUM(F16:G16) -> 0
A17: Total of Week 36 | F17: =SUMIF($B:$E,RIGHT($A17,2),F:F) -> 0 | G17: =SUMIF($B:$E,RIGHT($A17,2),G:G) -> 0 | H17: =SUMIF($B:$E,RIGHT($A17,2),H:H) -> 0
A19: Date | B19: Week | C19: Time Start | D19: Time End | E19: Activity | F19: Regular Hours | G19: Approved O/T | H19: Hours Billed
A20: =A16+1 -> 46272 | B20: =WEEKNUM(A20, 2) -> 37 | E20: Holiday: Labour Day | H20: =SUM(F20:G20) -> 0
A21: =A20+1 -> 46273 | B21: =WEEKNUM(A21, 2) -> 37 | H21: =SUM(F21:G21) -> 0
A22: =A21+1 -> 46274 | B22: =WEEKNUM(A22, 2) -> 37 | H22: =SUM(F22:G22) -> 0
A23: =A22+1 -> 46275 | B23: =WEEKNUM(A23, 2) -> 37 | H23: =SUM(F23:G23) -> 0
A24: =A23+1 -> 46276 | B24: =WEEKNUM(A24, 2) -> 37 | H24: =SUM(F24:G24) -> 0
A25: =A24+1 -> 46277 | B25: =WEEKNUM(A25, 2) -> 37 | H25: =SUM(F25:G25) -> 0
A26: =A25+1 -> 46278 | B26: =WEEKNUM(A26, 2) -> 37 | H26: =SUM(F26:G26) -> 0
A27: ="Total of Week "&RIGHT(A17,2)+1 -> Total of Week 37 | F27: =SUMIF($B:$E,RIGHT($A27,2),F:F) -> 0 | G27: =SUMIF($B:$E,RIGHT($A27,2),G:G) -> 0 | H27: =SUMIF($B:$E,RIGHT($A27,2),H:H) -> 0
A29: Date | B29: Week | C29: Time Start | D29: Time End | E29: Activity | F29: Regular Hours | G29: Approved O/T | H29: Hours Billed
A30: =A26+1 -> 46279 | B30: =WEEKNUM(A30, 2) -> 38 | H30: =SUM(F30:G30) -> 0
A31: =A30+1 -> 46280 | B31: =WEEKNUM(A31, 2) -> 38 | H31: =SUM(F31:G31) -> 0
A32: =A31+1 -> 46281 | B32: =WEEKNUM(A32, 2) -> 38 | H32: =SUM(F32:G32) -> 0
A33: =A32+1 -> 46282 | B33: =WEEKNUM(A33, 2) -> 38 | H33: =SUM(F33:G33) -> 0
A34: =A33+1 -> 46283 | B34: =WEEKNUM(A34, 2) -> 38 | H34: =SUM(F34:G34) -> 0
A35: =A34+1 -> 46284 | B35: =WEEKNUM(A35, 2) -> 38 | H35: =SUM(F35:G35) -> 0
A36: =A35+1 -> 46285 | B36: =WEEKNUM(A36, 2) -> 38 | H36: =SUM(F36:G36) -> 0
A37: ="Total of Week "&RIGHT(A27,2)+1 -> Total of Week 38 | F37: =SUMIF($B:$E,RIGHT($A37,2),F:F) -> 0 | G37: =SUMIF($B:$E,RIGHT($A37,2),G:G) -> 0 | H37: =SUMIF($B:$E,RIGHT($A37,2),H:H) -> 0
A39: Date | B39: Week | C39: Time Start | D39: Time End | E39: Activity | F39: Regular Hours | G39: Approved O/T | H39: Hours Billed
A40: =A36+1 -> 46286 | B40: =WEEKNUM(A40, 2) -> 39 | H40: =SUM(F40:G40) -> 0
A41: =A40+1 -> 46287 | B41: =WEEKNUM(A41, 2) -> 39 | H41: =SUM(F41:G41) -> 0
A42: =A41+1 -> 46288 | B42: =WEEKNUM(A42, 2) -> 39 | H42: =SUM(F42:G42) -> 0
A43: =A42+1 -> 46289 | B43: =WEEKNUM(A43, 2) -> 39 | H43: =SUM(F43:G43) -> 0
A44: =A43+1 -> 46290 | B44: =WEEKNUM(A44, 2) -> 39 | H44: =SUM(F44:G44) -> 0
...

Sheet October 2026
E1: Dawn InfoTek Inc.
J2: Contractor:
J3: 1. To be remitted to Manager/Project Leader by the last workday of each month
A4: Resource Name: | F4: Client Manager Name:
A5: Email Address: | F5: Office Phone: | J5: Manager/Project Leader:
A6: Date Submitted: | F6: Department Name: | J6: Please send to timesheet@dawninfotek.com after your approval monthly.
A7: Date Beginning: | F7: Project Leader Name:
A8: Date Ending:
A10: Date | B10: Week | C10: Time Start | D10: Time End | E10: Activity | F10: Regular Hours | G10: Approved O/T | H10: Hours Billed
A11: ='September 2026'!A52+1 -> 46296 | B11: =WEEKNUM(A11, 2) -> 40 | H11: =SUM(F11:G11) -> 0
A12: =A11+1 -> 46297 | B12: =WEEKNUM(A12, 2) -> 40 | H12: =SUM(F12:G12) -> 0
A13: =A12+1 -> 46298 | B13: =WEEKNUM(A13, 2) -> 40 | H13: =SUM(F13:G13) -> 0
A14: =A13+1 -> 46299 | B14: =WEEKNUM(A14, 2) -> 40 | H14: =SUM(F14:G14) -> 0
A15: Total of Week 40 | F15: =SUMIF($B:$E,RIGHT($A15,2),F:F) -> 0 | G15: =SUMIF($B:$E,RIGHT($A15,2),G:G) -> 0 | H15: =SUMIF($B:$E,RIGHT($A15,2),H:H) -> 0
A17: Date | B17: Week | C17: Time Start | D17: Time End | E17: Activity | F17: Regular Hours | G17: Approved O/T | H17: Hours Billed
A18: =A14+1 -> 46300 | B18: =WEEKNUM(A18, 2) -> 41 | H18: =SUM(F18:G18) -> 0
A19: =A18+1 -> 46301 | B19: =WEEKNUM(A19, 2) -> 41 | H19: =SUM(F19:G19) -> 0
A20: =A19+1 -> 46302 | B20: =WEEKNUM(A20, 2) -> 41 | H20: =SUM(F20:G20) -> 0
A21: =A20+1 -> 46303 | B21: =WEEKNUM(A21, 2) -> 41 | H21: =SUM(F21:G21) -> 0
A22: =A21+1 -> 46304 | B22: =WEEKNUM(A22, 2) -> 41 | H22: =SUM(F22:G22) -> 0
A23: =A22+1 -> 46305 | B23: =WEEKNUM(A23, 2) -> 41 | H23: =SUM(F23:G23) -> 0
A24: =A23+1 -> 46306 | B24: =WEEKNUM(A24, 2) -> 41 | H24: =SUM(F24:G24) -> 0
A25: ="Total of Week "&RIGHT(A15,2)+1 -> Total of Week 41 | F25: =SUMIF($B:$E,RIGHT($A25,2),F:F) -> 0 | G25: =SUMIF($B:$E,RIGHT($A25,2),G:G) -> 0 | H25: =SUMIF($B:$E,RIGHT($A25,2),H:H) -> 0
A27: Date | B27: Week | C27: Time Start | D27: Time End | E27: Activity | F27: Regular Hours | G27: Approved O/T | H27: Hours Billed
A28: =A24+1 -> 46307 | B28: =WEEKNUM(A28, 2) -> 42 | E28: Holiday: Thanksgiving | H28: =SUM(F28:G28) -> 0
A29: =A28+1 -> 46308 | B29: =WEEKNUM(A29, 2) -> 42 | H29: =SUM(F29:G29) -> 0
A30: =A29+1 -> 46309 | B30: =WEEKNUM(A30, 2) -> 42 | H30: =SUM(F30:G30) -> 0
A31: =A30+1 -> 46310 | B31: =WEEKNUM(A31, 2) -> 42 | H31: =SUM(F31:G31) -> 0
A32: =A31+1 -> 46311 | B32: =WEEKNUM(A32, 2) -> 42 | H32: =SUM(F32:G32) -> 0
A33: =A32+1 -> 46312 | B33: =WEEKNUM(A33, 2) -> 42 | H33: =SUM(F33:G33) -> 0
A34: =A33+1 -> 46313 | B34: =WEEKNUM(A34, 2) -> 42 | H34: =SUM(F34:G34) -> 0
A35: ="Total of Week "&RIGHT(A25,2)+1 -> Total of Week 42 | F35: =SUMIF($B:$E,RIGHT($A35,2),F:F) -> 0 | G35: =SUMIF($B:$E,RIGHT($A35,2),G:G) -> 0 | H35: =SUMIF($B:$E,RIGHT($A35,2),H:H) -> 0
A37: Date | B37: Week | C37: Time Start | D37: Time End | E37: Activity | F37: Regular Hours | G37: Approved O/T | H37: Hours Billed
A38: =A34+1 -> 46314 | B38: =WEEKNUM(A38, 2) -> 43 | H38: =SUM(F38:G38) -> 0
A39: =A38+1 -> 46315 | B39: =WEEKNUM(A39, 2) -> 43 | H39: =SUM(F39:G39) -> 0
A40: =A39+1 -> 46316 | B40: =WEEKNUM(A40, 2) -> 43 | H40: =SUM(F40:G40) -> 0
A41: =A40+1 -> 46317 | B41: =WEEKNUM(A41, 2) -> 43 | H41: =SUM(F41:G41) -> 0
A42: =A41+1 -> 46318 | B42: =WEEKNUM(A42, 2) -> 43 | H42: =SUM(F42:G42) -> 0
A43: =A42+1 -> 46319 | B43: =WEEKNUM(A43, 2) -> 43 | H43: =SUM(F43:G43) -> 0
A44: =A43+1 -> 46320 | B44: =WEEKNUM(A44, 2) -> 43 | H44: =SUM(F44:G44) -> 0
...

Sheet Novmber 2026
E1: Dawn InfoTek Inc.
J2: Contractor:
J3: 1. To be remitted to Manager/Project Leader by the last workday of each month
A4: Resource Name: | F4: Client Manager Name:
A5: Email Address: | F5: Office Phone: | J5: Manager/Project Leader:
A6: Date Submitted: | F6: Department Name: | J6: Please send to timesheet@dawninfotek.com after your approval monthly.
A7: Date Beginning: | F7: Project Leader Name:
A8: Date Ending:
A10: Date | B10: Week | C10: Time Start | D10: Time End | E10: Activity | F10: Regular Hours | G10: Approved O/T | H10: Hours Billed
A11: ='October 2026'!A53+1 -> 46327 | B11: =WEEKNUM(A11, 2) -> 44 | H11: =SUM(F11:G11) -> 0
A12: Total of Week 44 | F12: =SUMIF($B:$E,RIGHT($A12,2),F:F) -> 0 | G12: =SUMIF($B:$E,RIGHT($A12,2),G:G) -> 0 | H12: =SUMIF($B:$E,RIGHT($A12,2),H:H) -> 0
A14: Date | B14: Week | C14: Time Start | D14: Time End | E14: Activity | F14: Regular Hours | G14: Approved O/T | H14: Hours Billed
A15: =A11+1 -> 46328 | B15: =WEEKNUM(A15, 2) -> 45 | H15: =SUM(F15:G15) -> 0
A16: =A15+1 -> 46329 | B16: =WEEKNUM(A16, 2) -> 45 | H16: =SUM(F16:G16) -> 0
A17: =A16+1 -> 46330 | B17: =WEEKNUM(A17, 2) -> 45 | H17: =SUM(F17:G17) -> 0
A18: =A17+1 -> 46331 | B18: =WEEKNUM(A18, 2) -> 45 | H18: =SUM(F18:G18) -> 0
A19: =A18+1 -> 46332 | B19: =WEEKNUM(A19, 2) -> 45 | H19: =SUM(F19:G19) -> 0
A20: =A19+1 -> 46333 | B20: =WEEKNUM(A20, 2) -> 45 | H20: =SUM(F20:G20) -> 0
A21: =A20+1 -> 46334 | B21: =WEEKNUM(A21, 2) -> 45 | H21: =SUM(F21:G21) -> 0
A22: ="Total of Week "&RIGHT(A12,2)+1 -> Total of Week 45 | F22: =SUMIF($B:$E,RIGHT($A22,2),F:F) -> 0 | G22: =SUMIF($B:$E,RIGHT($A22,2),G:G) -> 0 | H22: =SUMIF($B:$E,RIGHT($A22,2),H:H) -> 0
A24: Date | B24: Week | C24: Time Start | D24: Time End | E24: Activity | F24: Regular Hours | G24: Approved O/T | H24: Hours Billed
A25: =A21+1 -> 46335 | B25: =WEEKNUM(A25, 2) -> 46 | H25: =SUM(F25:G25) -> 0
A26: =A25+1 -> 46336 | B26: =WEEKNUM(A26, 2) -> 46 | H26: =SUM(F26:G26) -> 0
A27: =A26+1 -> 46337 | B27: =WEEKNUM(A27, 2) -> 46 | E27: Bank Holiday: Remembrance Day | H27: =SUM(F27:G27) -> 0
A28: =A27+1 -> 46338 | B28: =WEEKNUM(A28, 2) -> 46 | H28: =SUM(F28:G28) -> 0
A29: =A28+1 -> 46339 | B29: =WEEKNUM(A29, 2) -> 46 | H29: =SUM(F29:G29) -> 0
A30: =A29+1 -> 46340 | B30: =WEEKNUM(A30, 2) -> 46 | H30: =SUM(F30:G30) -> 0
A31: =A30+1 -> 46341 | B31: =WEEKNUM(A31, 2) -> 46 | H31: =SUM(F31:G31) -> 0
A32: ="Total of Week "&RIGHT(A22,2)+1 -> Total of Week 46 | F32: =SUMIF($B:$E,RIGHT($A32,2),F:F) -> 0 | G32: =SUMIF($B:$E,RIGHT($A32,2),G:G) -> 0 | H32: =SUMIF($B:$E,RIGHT($A32,2),H:H) -> 0
A34: Date | B34: Week | C34: Time Start | D34: Time End | E34: Activity | F34: Regular Hours | G34: Approved O/T | H34: Hours Billed
A35: =A31+1 -> 46342 | B35: =WEEKNUM(A35, 2) -> 47 | H35: =SUM(F35:G35) -> 0
A36: =A35+1 -> 46343 | B36: =WEEKNUM(A36, 2) -> 47 | H36: =SUM(F36:G36) -> 0
A37: =A36+1 -> 46344 | B37: =WEEKNUM(A37, 2) -> 47 | H37: =SUM(F37:G37) -> 0
A38: =A37+1 -> 46345 | B38: =WEEKNUM(A38, 2) -> 47 | H38: =SUM(F38:G38) -> 0
A39: =A38+1 -> 46346 | B39: =WEEKNUM(A39, 2) -> 47 | H39: =SUM(F39:G39) -> 0
A40: =A39+1 -> 46347 | B40: =WEEKNUM(A40, 2) -> 47 | H40: =SUM(F40:G40) -> 0
A41: =A40+1 -> 46348 | B41: =WEEKNUM(A41, 2) -> 47 | H41: =SUM(F41:G41) -> 0
A42: ="Total of Week "&RIGHT(A32,2)+1 -> Total of Week 47 | F42: =SUMIF($B:$E,RIGHT($A42,2),F:F) -> 0 | G42: =SUMIF($B:$E,RIGHT($A42,2),G:G) -> 0 | H42: =SUMIF($B:$E,RIGHT($A42,2),H:H) -> 0
A44: Date | B44: Week | C44: Time Start | D44: Time End | E44: Activity | F44: Regular Hours | G44: Approved O/T | H44: Hours Billed
A45: =A41+1 -> 46349 | B45: =WEEKNUM(A45, 2) -> 48 | H45: =SUM(F45:G45) -> 0
...

Sheet December 2026
E1: Dawn InfoTek Inc.
J2: Contractor:
J3: 1. To be remitted to Manager/Project Leader by the last workday of each month
A4: Resource Name: | F4: Client Manager Name:
A5: Email Address: | F5: Office Phone: | J5: Manager/Project Leader:
A6: Date Submitted: | F6: Department Name: | J6: Please send to timesheet@dawninfotek.com after your approval monthly.
A7: Date Beginning: | F7: Project Leader Name:
A8: Date Ending:
A10: Date | B10: Week | C10: Time Start | D10: Time End | E10: Activity | F10: Regular Hours | G10: Approved O/T | H10: Hours Billed
A11: ='Novmber 2026'!A55+1 -> 46357 | B11: =WEEKNUM(A11, 2) -> 49 | H11: =SUM(F11:G11) -> 0
A12: =A11+1 -> 46358 | B12: =WEEKNUM(A12, 2) -> 49 | H12: =SUM(F12:G12) -> 0
A13: =A12+1 -> 46359 | B13: =WEEKNUM(A13, 2) -> 49 | H13: =SUM(F13:G13) -> 0
A14: =A13+1 -> 46360 | B14: =WEEKNUM(A14, 2) -> 49 | H14: =SUM(F14:G14) -> 0
A15: =A14+1 -> 46361 | B15: =WEEKNUM(A15, 2) -> 49 | H15: =SUM(F15:G15) -> 0
A16: =A15+1 -> 46362 | B16: =WEEKNUM(A16, 2) -> 49 | H16: =SUM(F16:G16) -> 0
A17: Total of Week 49 | F17: =SUMIF($B:$E,RIGHT($A17,2),F:F) -> 0 | G17: =SUMIF($B:$E,RIGHT($A17,2),G:G) -> 0 | H17: =SUMIF($B:$E,RIGHT($A17,2),H:H) -> 0
A19: Date | B19: Week | C19: Time Start | D19: Time End | E19: Activity | F19: Regular Hours | G19: Approved O/T | H19: Hours Billed
A20: =A16+1 -> 46363 | B20: =WEEKNUM(A20, 2) -> 50 | H20: =SUM(F20:G20) -> 0
A21: =A20+1 -> 46364 | B21: =WEEKNUM(A21, 2) -> 50 | H21: =SUM(F21:G21) -> 0
A22: =A21+1 -> 46365 | B22: =WEEKNUM(A22, 2) -> 50 | H22: =SUM(F22:G22) -> 0
A23: =A22+1 -> 46366 | B23: =WEEKNUM(A23, 2) -> 50 | H23: =SUM(F23:G23) -> 0
A24: =A23+1 -> 46367 | B24: =WEEKNUM(A24, 2) -> 50 | H24: =SUM(F24:G24) -> 0
A25: =A24+1 -> 46368 | B25: =WEEKNUM(A25, 2) -> 50 | H25: =SUM(F25:G25) -> 0
A26: =A25+1 -> 46369 | B26: =WEEKNUM(A26, 2) -> 50 | H26: =SUM(F26:G26) -> 0
A27: ="Total of Week "&RIGHT(A17,2)+1 -> Total of Week 50 | F27: =SUMIF($B:$E,RIGHT($A27,2),F:F) -> 0 | G27: =SUMIF($B:$E,RIGHT($A27,2),G:G) -> 0 | H27: =SUMIF($B:$E,RIGHT($A27,2),H:H) -> 0
A29: Date | B29: Week | C29: Time Start | D29: Time End | E29: Activity | F29: Regular Hours | G29: Approved O/T | H29: Hours Billed
A30: =A26+1 -> 46370 | B30: =WEEKNUM(A30, 2) -> 51 | H30: =SUM(F30:G30) -> 0
A31: =A30+1 -> 46371 | B31: =WEEKNUM(A31, 2) -> 51 | H31: =SUM(F31:G31) -> 0
A32: =A31+1 -> 46372 | B32: =WEEKNUM(A32, 2) -> 51 | H32: =SUM(F32:G32) -> 0
A33: =A32+1 -> 46373 | B33: =WEEKNUM(A33, 2) -> 51 | H33: =SUM(F33:G33) -> 0
A34: =A33+1 -> 46374 | B34: =WEEKNUM(A34, 2) -> 51 | H34: =SUM(F34:G34) -> 0
A35: =A34+1 -> 46375 | B35: =WEEKNUM(A35, 2) -> 51 | H35: =SUM(F35:G35) -> 0
A36: =A35+1 -> 46376 | B36: =WEEKNUM(A36, 2) -> 51 | H36: =SUM(F36:G36) -> 0
A37: ="Total of Week "&RIGHT(A27,2)+1 -> Total of Week 51 | F37: =SUMIF($B:$E,RIGHT($A37,2),F:F) -> 0 | G37: =SUMIF($B:$E,RIGHT($A37,2),G:G) -> 0 | H37: =SUMIF($B:$E,RIGHT($A37,2),H:H) -> 0
A39: Date | B39: Week | C39: Time Start | D39: Time End | E39: Activity | F39: Regular Hours | G39: Approved O/T | H39: Hours Billed
A40: =A36+1 -> 46377 | B40: =WEEKNUM(A40, 2) -> 52 | H40: =SUM(F40:G40) -> 0
A41: =A40+1 -> 46378 | B41: =WEEKNUM(A41, 2) -> 52 | H41: =SUM(F41:G41) -> 0
A42: =A41+1 -> 46379 | B42: =WEEKNUM(A42, 2) -> 52 | H42: =SUM(F42:G42) -> 0
A43: =A42+1 -> 46380 | B43: =WEEKNUM(A43, 2) -> 52 | H43: =SUM(F43:G43) -> 0
A44: =A43+1 -> 46381 | B44: =WEEKNUM(A44, 2) -> 52 | E44: Holiday: Christmas | H44: =SUM(F44:G44) -> 0
...
